Workbook

Sheet Cover
B2: Finance Operations Automation Project
B3: Reconciliation · AP · AR · Compliance · Risk · Procurement · Forecasting · Reporting Automation
B4: Data coverage: Jan 2025 – Jul 2026 | Built for Excel (legacy, non-365 compatible — no XLOOKUP / Power Query)
B6: How this workbook is organized
B8: Cover / Assumptions | C8: This sheet + editable As-Of date and risk thresholds (yellow cells).
B9: Raw Data (9 grey tabs) | C9: Untouched source tables: Vendor/Customer Master, POs, GRNs, AP Invoices, AP Payments, Bank Statement, AR Invoices, AR Receipts.
B10: 3Way_Match | C10: Reconciliation Module 1: PO ↔ GRN ↔ Invoice matching, flags amount mismatches & goods invoiced but not received.
B11: Bank_Reconciliation | C11: Reconciliation Module 2: AP payments ↔ bank statement matching, flags unmatched items and timing/amount differences.
B12: AP_Aging | C12: Outstanding AP invoices bucketed 0-30/31-60/61-90/90+ days.
B13: Duplicate_Payments | C13: Flags invoices paid more than once.
B14: DPO_Summary | C14: Days Payable Outstanding — headline metric + monthly trend.
B15: AR_Aging | C15: Outstanding AR invoices bucketed 0-30/31-60/61-90/90+ days.
B16: AR_Partial_Unpaid | C16: Flags short-paid and fully overdue customer invoices.
B17: DSO_Summary | C17: Days Sales Outstanding — headline metric + monthly trend.
B18: SoD_Check | C18: Segregation-of-Duties: flags POs where requester = approver.
B19: RCM | C19: Risk & Control Matrix — internal-audit style pass/fail summary, auto-updating from the modules above.
... B25: KPI_Dashboard | C25: One-page summary with headline KPIs and charts.
B27: See the separate Project Documentation (Word) and How-To-Run Guide for full methodology and the VBA automation setup.

Sheet Assumptions
A1: Assumptions & Editable Inputs
A2: Yellow cells are inputs — change them and every module recalculates.
A4: Assumption | B4: Value | C4: Notes
A5: Reporting As-Of Date | B5: 2026-07-31 | C5: Used by every Aging / DPO / DSO / Forecast module as 'today'. Data runs through Jul-2026 in the source file.
A6: Match Tolerance ($) | B6: 1 | C6: Dollar variance allowed before a 3-way-match / bank line is flagged as a mismatch.
A7: Large Transaction Threshold ($) | B7: 10000 | C7: Risk scoring: amount at/above this adds high points.
A8: Elevated Transaction Threshold ($) | B8: 5000 | C8: Risk scoring: amount at/above this (but below Large) adds medium points.
A9: New Vendor Window (days) | B9: 180 | C9: Vendor is 'new' if onboarded within this many days of the transaction/report date.
A10: Higher-Risk Countries | B10: India, UAE, Singapore | C10: Illustrative geography flag for the AML-style score — replace with your AML policy's actual list.
A11: AP Aging Buckets (days) | B11: 0-30 / 31-60 / 61-90 / 90+ | C11: Standard 4-bucket aging, matches AR for consistency.

Sheet Vendor_Master
A1: Vendor_ID | B1: Vendor_Name | C1: Category | D1: Country | E1: Onboarding_Date | F1: Bank_Account_Last4 | G1: Payment_Terms_Days
A2: V1001 | B2: Figueroa and Sons | C2: Travel & Logistics | D2: USA | E2: 45572 | F2: 1409 | G2: 45
A3: V1002 | B3: Garcia, Yang and Gardner | C3: Office Supplies | D3: UK | E3: 44914 | F3: 3286 | G3: 15
A4: V1003 | B4: Johnson and Sons | C4: Travel & Logistics | D4: UAE | E4: 45495 | F4: 9935 | G4: 15
A5: V1004 | B5: Johnson, Gonzalez and Santos | C5: Marketing | D5: Germany | E5: 44929 | F5: 1520 | G5: 15
A6: V1005 | B6: Cole LLC | C6: IT Services | D6: UK | E6: 45423 | F6: 4811 | G6: 15
A7: V1006 | B7: Blake and Sons | C7: Marketing | D7: UK | E7: 45841 | F7: 9928 | G7: 60
A8: V1007 | B8: Ramirez-Lewis | C8: Office Supplies | D8: Germany | E8: 45665 | F8: 5557 | G8: 15
A9: V1008 | B9: Davis Inc | C9: Software Licensing | D9: Canada | E9: 45769 | F9: 3615 | G9: 60
A10: V1009 | B10: Munoz-Roman | C10: Professional Services | D10: India | E10: 45129 | F10: 3547 | G10: 30
A11: V1010 | B11: Martinez, Nielsen and Miller | C11: Software Licensing | D11: India | E11: 45715 | F11: 2674 | G11: 15
A12: V1011 | B12: Montgomery, Hensley and Ray | C12: Facilities | D12: USA | E12: 45025 | F12: 6881 | G12: 45
A13: V1012 | B13: Stanley LLC | C13: Marketing | D13: India | E13: 45675 | F13: 1711 | G13: 60
... A41: V1040 | B41: Santos, Kim and Holmes | C41: Office Supplies | D41: India | E41: 45192 | F41: 3646 | G41: 15

Sheet Customer_Master
A1: Customer_ID | B1: Customer_Name | C1: Country | D1: Credit_Terms_Days | E1: Industry
A2: C2001 | B2: Wright Inc | C2: Singapore | D2: 45 | E2: Technology
A3: C2002 | B3: Smith-Spencer | C3: USA | D3: 15 | E3: Healthcare
A4: C2003 | B4: Robinson, Jones and Welch | C4: Canada | D4: 45 | E4: Manufacturing
A5: C2004 | B5: Jones Inc | C5: USA | D5: 30 | E5: Financial Services
A6: C2005 | B6: Jones-Young | C6: USA | D6: 15 | E6: Technology
A7: C2006 | B7: Washington, Ryan and Cummings | C7: Canada | D7: 15 | E7: Financial Services
A8: C2007 | B8: Johnston, Sanchez and Kennedy | C8: Canada | D8: 30 | E8: Manufacturing
A9: C2008 | B9: Lee-Davis | C9: UAE | D9: 60 | E9: Financial Services
A10: C2009 | B10: Gomez-Jenkins | C10: UK | D10: 45 | E10: Financial Services
A11: C2010 | B11: Brown, Valdez and Lucas | C11: Canada | D11: 60 | E11: Manufacturing
A12: C2011 | B12: Powell LLC | C12: Singapore | D12: 30 | E12: Healthcare
A13: C2012 | B13: Wright and Sons | C13: Germany | D13: 45 | E13: Technology
... A31: C2030 | B31: Sanchez, Wheeler and Harvey | C31: Canada | D31: 15 | E31: Manufacturing

Sheet Purchase_Orders
A1: PO_ID | B1: Vendor_ID | C1: PO_Date | D1: PO_Amount | E1: Category | F1: Requested_By | G1: Approved_By
A2: PO10001 | B2: V1020 | C2: 46091 | D2: 1309.32 | E2: Travel & Logistics | F2: Shirley Suarez | G2: Evelyn Galvan
A3: PO10002 | B3: V1034 | C3: 45782 | D3: 1749.66 | E3: Marketing | F3: Jimmy Murillo | G3: Shannon Walker
A4: PO10003 | B4: V1014 | C4: 45670 | D4: 2691.35 | E4: Marketing | F4: John Whitehead | G4: Evelyn Galvan
A5: PO10004 | B5: V1040 | C5: 45763 | D5: 889.24 | E5: Office Supplies | F5: James Powers | G5: Julia Torres
A6: PO10005 | B6: V1022 | C6: 45836 | D6: 3058.04 | E6: Facilities | F6: Deborah Figueroa | G6: Sharon Cherry
A7: PO10006 | B7: V1040 | C7: 46129 | D7: 1359.77 | E7: Office Supplies | F7: Deborah Figueroa | G7: Marc Moore
A8: PO10007 | B8: V1040 | C8: 46184 | D8: 3708.39 | E8: Office Supplies | F8: Richard Henson | G8: Evelyn Galvan
A9: PO10008 | B9: V1015 | C9: 45810 | D9: 6081.19 | E9: Travel & Logistics | F9: Anna Henderson | G9: Julia Torres
A10: PO10009 | B10: V1018 | C10: 46007 | D10: 6038.81 | E10: Facilities | F10: Denise Jacobs | G10: Marc Moore
A11: PO10010 | B11: V1005 | C11: 45875 | D11: 1250.19 | E11: IT Services | F11: Kevin Mills | G11: Shannon Walker
A12: PO10011 | B12: V1024 | C12: 46192 | D12: 760.24 | E12: Software Licensing | F12: John Whitehead | G12: Sharon Cochran
A13: PO10012 | B13: V1035 | C13: 45950 | D13: 15002.72 | E13: Marketing | F13: Christine Wright | G13: Julia Torres
... A851: PO10850 | B851: V1014 | C851: 45970 | D851: 4104.49 | E851: Marketing | F851: Stephen Mckee | G851: Shannon Walker

Sheet Goods_Receipt_Notes
A1: GRN_ID | B1: PO_ID | C1: Receipt_Date | D1: Received_Amount
A2: GRN20486 | B2: PO10487 | C2: 45690 | D2: 542.8
A3: GRN20559 | B3: PO10560 | C3: 45986 | D3: 829.86
A4: GRN20185 | B4: PO10186 | C4: 46079 | D4: 3351.54
A5: GRN20806 | B5: PO10807 | C5: 46100 | D5: 830.55
A6: GRN20493 | B6: PO10494 | C6: 45912 | D6: 607.61
A7: GRN20298 | B7: PO10299 | C7: 45957 | D7: 8486.94
A8: GRN20842 | B8: PO10843 | C8: 45703 | D8: 2224.01
A9: GRN20776 | B9: PO10777 | C9: 45863 | D9: 1467.37
A10: GRN20752 | B10: PO10753 | C10: 46125 | D10: 4765.29
A11: GRN20755 | B11: PO10756 | C11: 46079 | D11: 305.02
A12: GRN20008 | B12: PO10009 | C12: 46013 | D12: 6038.81
A13: GRN20819 | B13: PO10820 | C13: 45738 | D13: 424.45
... A791: GRN20466 | B791: PO10467 | C791: 45968 | D791: 2324.66

Sheet Vendor_Invoices_AP
A1: Invoice_ID | B1: PO_ID | C1: Vendor_ID | D1: Invoice_Date | E1: Invoice_Amount | F1: Due_Date
A2: INV30001 | B2: PO10001 | C2: V1020 | D2: 46109 | E2: 1417.41 | F2: 46139
A3: INV30002 | B3: PO10002 | C3: V1034 | D3: 45803 | E3: 1749.66 | F3: 45848
A4: INV30003 | B4: PO10003 | C4: V1014 | D4: 45676 | E4: 2691.35 | F4: 45706
A5: INV30004 | B5: PO10004 | C5: V1040 | D5: 45783 | E5: 889.24 | F5: 45798
A6: INV30005 | B6: PO10005 | C6: V1022 | D6: 45861 | E6: 3058.04 | F6: 45891
A7: INV30006 | B7: PO10006 | C7: V1040 | D7: 46132 | E7: 1359.77 | F7: 46147
A8: INV30007 | B8: PO10007 | C8: V1040 | D8: 46188 | E8: 3708.39 | F8: 46203
A9: INV30008 | B9: PO10008 | C9: V1015 | D9: 45833 | E9: 6081.19 | F9: 45863
A10: INV30009 | B10: PO10009 | C10: V1018 | D10: 46020 | E10: 6038.81 | F10: 46050
A11: INV30010 | B11: PO10010 | C11: V1005 | D11: 45878 | E11: 1466.07 | F11: 45893
A12: INV30011 | B12: PO10011 | C12: V1024 | D12: 46210 | E12: 760.24 | F12: 46270
A13: INV30012 | B13: PO10012 | C13: V1035 | D13: 45975 | E13: 15002.72 | F13: 45990
... A882: INV30881 | B882: PO10850 | C882: V1014 | D882: 45973 | E882: 4104.49 | F882: 46003

Sheet Payment_Log_AP
A1: Payment_ID | B1: Invoice_ID | C1: Vendor_ID | D1: Payment_Date | E1: Payment_Amount | F1: Approved_By
A2: PAY40001 | B2: INV30001 | C2: V1020 | D2: 46142 | E2: 1417.41 | F2: Shannon Walker
A3: PAY40002 | B3: INV30002 | C3: V1034 | D3: 45805 | E3: 1749.66 | F3: Richard Rodriguez
A4: PAY40003 | B4: INV30003 | C4: V1014 | D4: 45683 | E4: 2691.35 | F4: Julia Torres
A5: PAY40004 | B5: INV30004 | C5: V1040 | D5: 45805 | E5: 889.24 | F5: Julia Torres
A6: PAY40005 | B6: INV30005 | C6: V1022 | D6: 45883 | E6: 3058.04 | F6: Sierra Johnson
A7: PAY40006 | B7: INV30006 | C7: V1040 | D7: 46160 | E7: 1359.77 | F7: Evelyn Galvan
A8: PAY40007 | B8: INV30007 | C8: V1040 | D8: 46193 | E8: 3708.39 | F8: Evelyn Galvan
A9: PAY40008 | B9: INV30008 | C9: V1015 | D9: 45859 | E9: 6081.19 | F9: Evelyn Galvan
A10: PAY40009 | B10: INV30010 | C10: V1005 | D10: 45885 | E10: 1466.07 | F10: Richard Rodriguez
A11: PAY40010 | B11: INV30012 | C11: V1035 | D11: 45989 | E11: 15002.72 | F11: Richard Rodriguez
A12: PAY40011 | B12: INV30013 | C12: V1016 | D12: 46196 | E12: 911.91 | F12: Sharon Cochran
A13: PAY40012 | B13: INV30014 | C13: V1002 | D13: 45753 | E13: 1222.88 | F13: Shannon Walker
... A753: PAY40752 | B753: INV30881 | C753: V1014 | D753: 46002 | E753: 4104.49 | F753: Shannon Walker

Sheet Bank_Statement
A1: Bank_Txn_ID | B1: Date | C1: Amount | D1: Description | E1: Matched_Payment_ID
A2: BNK50001 | B2: 46144 | C2: -1417.41 | D2: PMT-V1020 | E2: PAY40001
A3: BNK50002 | B3: 45807 | C3: -1749.66 | D3: PMT-V1034 | E3: PAY40002
A4: BNK50003 | B4: 45683 | C4: -2691.35 | D4: PMT-V1014 | E4: PAY40003
A5: BNK50004 | B5: 45808 | C5: -889.24 | D5: PMT-V1040 | E5: PAY40004
A6: BNK50005 | B6: 45886 | C6: -3058.04 | D6: PMT-V1022 | E6: PAY40005
A7: BNK50006 | B7: 46161 | C7: -1359.77 | D7: PMT-V1040 | E7: PAY40006
A8: BNK50007 | B8: 46195 | C8: -3708.39 | D8: PMT-V1040 | E8: PAY40007
A9: BNK50008 | B9: 45861 | C9: -6081.19 | D9: PMT-V1015 | E9: PAY40008
A10: BNK50009 | B10: 45885 | C10: -1466.07 | D10: PMT-V1005 | E10: PAY40009
A11: BNK50010 | B11: 45992 | C11: -15002.72 | D11: PMT-V1035 | E11: PAY40010
A12: BNK50011 | B12: 46197 | C12: -911.91 | D12: PMT-V1016 | E12: PAY40011
A13: BNK50012 | B13: 45753 | C13: -1222.88 | D13: PMT-V1002 | E13: PAY40012
... A753: BNK50752 | B753: 46002 | C753: -4104.49 | D753: PMT-V1014 | E753: PAY40752
A754: BNK50753 | B754: 46044 | C754: -20.43 | D754: Bank Service Charge
A755: BNK50754 | B755: 45885 | C755: -142.45 | D755: FX Adjustment
A756: BNK50755 | B756: 45720 | C756: -198.25 | D756: Bank Service Charge
A757: BNK50756 | B757: 45669 | C757: -39.26 | D757: FX Adjustment
A758: BNK50757 | B758: 45834 | C758: -198.13 | D758: Bank Service Charge
A759: BNK50758 | B759: 46094 | C759: -432.76 | D759: Wire Transfer Fee
A760: BNK50759 | B760: 45994 | C760: -227.57 | D760: Bank Service Charge
A761: BNK50760 | B761: 46111 | C761: -110.81 | D761: Bank Service Charge
A762: BNK50761 | B762: 46159 | C762: -333.36 | D762: FX Adjustment
A763: BNK50762 | B763: 45706 | C763: -35.61 | D763: Wire Transfer Fee
A764: BNK50763 | B764: 46118 | C764: -25.34 | D764: Wire Transfer Fee
A765: BNK50764 | B765: 45790 | C765: -469.24 | D765: FX Adjustment
... A783: BNK50782 | B783: 45765 | C783: -475.97 | D783: Bank Service Charge

Sheet Customer_Invoices_AR
A1: AR_Invoice_ID | B1: Customer_ID | C1: Billing_Date | D1: Invoice_Amount | E1: Due_Date
A2: ARI60001 | B2: C2003 | C2: 45986 | D2: 6493.93 | E2: 46031
A3: ARI60002 | B3: C2014 | C3: 46072 | D3: 3250.9 | E3: 46102
A4: ARI60003 | B4: C2010 | C4: 46015 | D4: 715.25 | E4: 46075
A5: ARI60004 | B5: C2030 | C5: 45754 | D5: 3252.02 | E5: 45769
A6: ARI60005 | B6: C2014 | C6: 46079 | D6: 6622.57 | E6: 46109
A7: ARI60006 | B7: C2004 | C7: 45927 | D7: 8576.41 | E7: 45957
A8: ARI60007 | B8: C2027 | C8: 46069 | D8: 4091.62 | E8: 46129
A9: ARI60008 | B9: C2009 | C9: 46072 | D9: 673.49 | E9: 46117
A10: ARI60009 | B10: C2027 | C10: 45902 | D10: 4452.11 | E10: 45962
A11: ARI60010 | B11: C2008 | C11: 46161 | D11: 6127.03 | E11: 46221
A12: ARI60011 | B12: C2001 | C12: 45965 | D12: 3666.96 | E12: 46010
A13: ARI60012 | B13: C2016 | C13: 46004 | D13: 8288.62 | E13: 46034
... A601: ARI60600 | B601: C2021 | C601: 45706 | D601: 3855.14 | E601: 45766

Sheet Cash_Receipts_AR
A1: Receipt_ID | B1: AR_Invoice_ID | C1: Customer_ID | D1: Receipt_Date | E1: Receipt_Amount
A2: ARR70001 | B2: ARI60002 | C2: C2014 | D2: 46095 | E2: 1523.91
A3: ARR70002 | B3: ARI60003 | C3: C2010 | D3: 46049 | E3: 715.25
A4: ARR70003 | B4: ARI60004 | C4: C2030 | D4: 45766 | E4: 3252.02
A5: ARR70004 | B5: ARI60005 | C5: C2014 | D5: 46115 | E5: 6622.57
A6: ARR70005 | B6: ARI60006 | C6: C2004 | D6: 45970 | E6: 2625.84
A7: ARR70006 | B7: ARI60007 | C7: C2027 | D7: 46106 | E7: 4091.62
A8: ARR70007 | B8: ARI60008 | C8: C2009 | D8: 46083 | E8: 673.49
A9: ARR70008 | B9: ARI60009 | C9: C2027 | D9: 45935 | E9: 2365.68
A10: ARR70009 | B10: ARI60010 | C10: C2008 | D10: 46185 | E10: 6127.03
A11: ARR70010 | B11: ARI60011 | C11: C2001 | D11: 45982 | E11: 3666.96
A12: ARR70011 | B12: ARI60012 | C12: C2016 | D12: 46034 | E12: 8288.62
A13: ARR70012 | B13: ARI60013 | C13: C2025 | D13: 45999 | E13: 1708.27
... A503: ARR70502 | B503: ARI60600 | C503: C2021 | D503: 45739 | E503: 3855.14

Sheet 3Way_Match
A1: Reconciliation Module 1 — Three-Way Match (PO ↔ GRN ↔ Invoice)
A2: Base table: Purchase_Orders. Flags goods invoiced without receipt and amount mismatches beyond the tolerance in Assumptions!B6.
A4: PO_ID | B4: Vendor_ID | C4: Vendor_Name | D4: PO_Date | E4: PO_Amount | F4: GRN_Received_Amount | G4: Invoice_Amount | H4: Received_Flag | I4: Invoiced_Flag | J4: PO_vs_GRN_Variance | K4: PO_vs_Invoice_Variance | L4: Exception_Flag
A5: =Purchase_Orders!A2 -> PO10001 | B5: =Purchase_Orders!B2 -> V1020 | C5: =IFERROR(INDEX(Vendor_Master!$B$2:$B$41,MATCH(B5,Vendor_Master!$A$2:$A$41,0)),"Unknown Vendor") -> Lewis-Porter | D5: =Purchase_Orders!C2 -> 46091 | E5: =Purchase_Orders!D2 -> 1309.32 | F5: =SUMIFS(Goods_Receipt_Notes!$D$2:$D$791,Goods_Receipt_Notes!$B$2:$B$791,A5) -> 1309.32 | G5: =SUMIFS(Vendor_Invoices_AP!$E$2:$E$882,Vendor_Invoices_AP!$B$2:$B$882,A5) -> 1417.41 | H5: =IF(F5=0,"Not Received","Received") -> Received | I5: =IF(G5=0,"Not Invoiced","Invoiced") -> Invoiced | J5: =E5-F5 -> 0 | K5: =E5-G5 -> -108.09 | L5: =IF(OR(AND(I5="Invoiced",H5="Not Received"),AND(F5>0,ABS(J5)>Assumptions!$B$6),AND(G5>0,ABS(K5)>Assumptions!$B$6)),"EXCEPTION","OK") -> EXCEPTION
A6: =Purchase_Orders!A3 -> PO10002 | B6: =Purchase_Orders!B3 -> V1034 | C6: =IFERROR(INDEX(Vendor_Master!$B$2:$B$41,MATCH(B6,Vendor_Master!$A$2:$A$41,0)),"Unknown Vendor") -> Koch-Decker | D6: =Purchase_Orders!C3 -> 45782 | E6: =Purchase_Orders!D3 -> 1749.66 | F6: =SUMIFS(Goods_Receipt_Notes!$D$2:$D$791,Goods_Receipt_Notes!$B$2:$B$791,A6) -> 1749.66 | G6: =SUMIFS(Vendor_Invoices_AP!$E$2:$E$882,Vendor_Invoices_AP!$B$2:$B$882,A6) -> 1749.66 | H6: =IF(F6=0,"Not Received","Received") -> Received | I6: =IF(G6=0,"Not Invoiced","Invoiced") -> Invoiced | J6: =E6-F6 -> 0 | K6: =E6-G6 -> 0 | L6: =IF(OR(AND(I6="Invoiced",H6="Not Received"),AND(F6>0,ABS(J6)>Assumptions!$B$6),AND(G6>0,ABS(K6)>Assumptions!$B$6)),"EXCEPTION","OK") -> OK
A7: =Purchase_Orders!A4 -> PO10003 | B7: =Purchase_Orders!B4 -> V1014 | C7: =IFERROR(INDEX(Vendor_Master!$B$2:$B$41,MATCH(B7,Vendor_Master!$A$2:$A$41,0)),"Unknown Vendor") -> Flowers, Martin and Kelly | D7: =Purchase_Orders!C4 -> 45670 | E7: =Purchase_Orders!D4 -> 2691.35 | F7: =SUMIFS(Goods_Receipt_Notes!$D$2:$D$791,Goods_Receipt_Notes!$B$2:$B$791,A7) -> 1676.95 | G7: =SUMIFS(Vendor_Invoices_AP!$E$2:$E$882,Vendor_Invoices_AP!$B$2:$B$882,A7) -> 2691.35 | H7: =IF(F7=0,"Not Received","Received") -> Received | I7: =IF(G7=0,"Not Invoiced","Invoiced") -> Invoiced | J7: =E7-F7 -> 1014.4 | K7: =E7-G7 -> 0 | L7: =IF(OR(AND(I7="Invoiced",H7="Not Received"),AND(F7>0,ABS(J7)>Assumptions!$B$6),AND(G7>0,ABS(K7)>Assumptions!$B$6)),"EXCEPTION","OK") -> EXCEPTION
A8: =Purchase_Orders!A5 -> PO10004 | B8: =Purchase_Orders!B5 -> V1040 | C8: =IFERROR(INDEX(Vendor_Master!$B$2:$B$41,MATCH(B8,Vendor_Master!$A$2:$A$41,0)),"Unknown Vendor") -> Santos, Kim and Holmes | D8: =Purchase_Orders!C5 -> 45763 | E8: =Purchase_Orders!D5 -> 889.24 | F8: =SUMIFS(Goods_Receipt_Notes!$D$2:$D$791,Goods_Receipt_Notes!$B$2:$B$791,A8) -> 889.24 | G8: =SUMIFS(Vendor_Invoices_AP!$E$2:$E$882,Vendor_Invoices_AP!$B$2:$B$882,A8) -> 889.24 | H8: =IF(F8=0,"Not Received","Received") -> Received | I8: =IF(G8=0,"Not Invoiced","Invoiced") -> Invoiced | J8: =E8-F8 -> 0 | K8: =E8-G8 -> 0 | L8: =IF(OR(AND(I8="Invoiced",H8="Not Received"),AND(F8>0,ABS(J8)>Assumptions!$B$6),AND(G8>0,ABS(K8)>Assumptions!$B$6)),"EXCEPTION","OK") -> OK
A9: =Purchase_Orders!A6 -> PO10005 | B9: =Purchase_Orders!B6 -> V1022 | C9: =IFERROR(INDEX(Vendor_Master!$B$2:$B$41,MATCH(B9,Vendor_Master!$A$2:$A$41,0)),"Unknown Vendor") -> Burgess-Patterson | D9: =Purchase_Orders!C6 -> 45836 | E9: =Purchase_Orders!D6 -> 3058.04 | F9: =SUMIFS(Goods_Receipt_Notes!$D$2:$D$791,Goods_Receipt_Notes!$B$2:$B$791,A9) -> 3058.04 | G9: =SUMIFS(Vendor_Invoices_AP!$E$2:$E$882,Vendor_Invoices_AP!$B$2:$B$882,A9) -> 3058.04 | H9: =IF(F9=0,"Not Received","Received") -> Received | I9: =IF(G9=0,"Not Invoiced","Invoiced") -> Invoiced | J9: =E9-F9 -> 0 | K9: =E9-G9 -> 0 | L9: =IF(OR(AND(I9="Invoiced",H9="Not Received"),AND(F9>0,ABS(J9)>Assumptions!$B$6),AND(G9>0,ABS(K9)>Assumptions!$B$6)),"EXCEPTION","OK") -> OK
A10: =Purchase_Orders!A7 -> PO10006 | B10: =Purchase_Orders!B7 -> V1040 | C10: =IFERROR(INDEX(Vendor_Master!$B$2:$B$41,MATCH(B10,Vendor_Master!$A$2:$A$41,0)),"Unknown Vendor") -> Santos, Kim and Holmes | D10: =Purchase_Orders!C7 -> 46129 | E10: =Purchase_Orders!D7 -> 1359.77 | F10: =SUMIFS(Goods_Receipt_Notes!$D$2:$D$791,Goods_Receipt_Notes!$B$2:$B$791,A10) -> 1359.77 | G10: =SUMIFS(Vendor_Invoices_AP!$E$2:$E$882,Vendor_Invoices_AP!$B$2:$B$882,A10) -> 1359.77 | H10: =IF(F10=0,"Not Received","Received") -> Received | I10: =IF(G10=0,"Not Invoiced","Invoiced") -> Invoiced | J10: =E10-F10 -> 0 | K10: =E10-G10 -> 0 | L10: =IF(OR(AND(I10="Invoiced",H10="Not Received"),AND(F10>0,ABS(J10)>Assumptions!$B$6),AND(G10>0,ABS(K10)>Assumptions!$B$6)),"EXCEPTION","OK") -> OK
A11: =Purchase_Orders!A8 -> PO10007 | B11: =Purchase_Orders!B8 -> V1040 | C11: =IFERROR(INDEX(Vendor_Master!$B$2:$B$41,MATCH(B11,Vendor_Master!$A$2:$A$41,0)),"Unknown Vendor") -> Santos, Kim and Holmes | D11: =Purchase_Orders!C8 -> 46184 | E11: =Purchase_Orders!D8 -> 3708.39 | F11: =SUMIFS(Goods_Receipt_Notes!$D$2:$D$791,Goods_Receipt_Notes!$B$2:$B$791,A11) -> 3708.39 | G11: =SUMIFS(Vendor_Invoices_AP!$E$2:$E$882,Vendor_Invoices_AP!$B$2:$B$882,A11) -> 3708.39 | H11: =IF(F11=0,"Not Received","Received") -> Received | I11: =IF(G11=0,"Not Invoiced","Invoiced") -> Invoiced | J11: =E11-F11 -> 0 | K11: =E11-G11 -> 0 | L11: =IF(OR(AND(I11="Invoiced",H11="Not Received"),AND(F11>0,ABS(J11)>Assumptions!$B$6),AND(G11>0,ABS(K11)>Assumptions!$B$6)),"EXCEPTION","OK") -> OK
A12: =Purchase_Orders!A9 -> PO10008 | B12: =Purchase_Orders!B9 -> V1015 | C12: =IFERROR(INDEX(Vendor_Master!$B$2:$B$41,MATCH(B12,Vendor_Master!$A$2:$A$41,0)),"Unknown Vendor") -> Zuniga, Wong and Lynch | D12: =Purchase_Orders!C9 -> 45810 | E12: =Purchase_Orders!D9 -> 6081.19 | F12: =SUMIFS(Goods_Receipt_Notes!$D$2:$D$791,Goods_Receipt_Notes!$B$2:$B$791,A12) -> 0 | G12: =SUMIFS(Vendor_Invoices_AP!$E$2:$E$882,Vendor_Invoices_AP!$B$2:$B$882,A12) -> 6081.19 | H12: =IF(F12=0,"Not Received","Received") -> Not Received | I12: =IF(G12=0,"Not Invoiced","Invoiced") -> Invoiced | J12: =E12-F12 -> 6081.19 | K12: =E12-G12 -> 0 | L12: =IF(OR(AND(I12="Invoiced",H12="Not Received"),AND(F12>0,ABS(J12)>Assumptions!$B$6),AND(G12>0,ABS(K12)>Assumptions!$B$6)),"EXCEPTION","OK") -> EXCEPTION
A13: =Purchase_Orders!A10 -> PO10009 | B13: =Purchase_Orders!B10 -> V1018 | C13: =IFERROR(INDEX(Vendor_Master!$B$2:$B$41,MATCH(B13,Vendor_Master!$A$2:$A$41,0)),"Unknown Vendor") -> Underwood LLC | D13: =Purchase_Orders!C10 -> 46007 | E13: =Purchase_Orders!D10 -> 6038.81 | F13: =SUMIFS(Goods_Receipt_Notes!$D$2:$D$791,Goods_Receipt_Notes!$B$2:$B$791,A13) -> 6038.81 | G13: =SUMIFS(Vendor_Invoices_AP!$E$2:$E$882,Vendor_Invoices_AP!$B$2:$B$882,A13) -> 6038.81 | H13: =IF(F13=0,"Not Received","Received") -> Received | I13: =IF(G13=0,"Not Invoiced","Invoiced") -> Invoiced | J13: =E13-F13 -> 0 | K13: =E13-G13 -> 0 | L13: =IF(OR(AND(I13="Invoiced",H13="Not Received"),AND(F13>0,ABS(J13)>Assumptions!$B$6),AND(G13>0,ABS(K13)>Assumptions!$B$6)),"EXCEPTION","OK") -> OK
A14: =Purchase_Orders!A11 -> PO10010 | B14: =Purchase_Orders!B11 -> V1005 | C14: =IFERROR(INDEX(Vendor_Master!$B$2:$B$41,MATCH(B14,Vendor_Master!$A$2:$A$41,0)),"Unknown Vendor") -> Cole LLC | D14: =Purchase_Orders!C11 -> 45875 | E14: =Purchase_Orders!D11 -> 1250.19 | F14: =SUMIFS(Goods_Receipt_Notes!$D$2:$D$791,Goods_Receipt_Notes!$B$2:$B$791,A14) -> 721.2 | G14: =SUMIFS(Vendor_Invoices_AP!$E$2:$E$882,Vendor_Invoices_AP!$B$2:$B$882,A14) -> 1466.07 | H14: =IF(F14=0,"Not Received","Received") -> Received | I14: =IF(G14=0,"Not Invoiced","Invoiced") -> Invoiced | J14: =E14-F14 -> 528.99 | K14: =E14-G14 -> -215.88 | L14: =IF(OR(AND(I14="Invoiced",H14="Not Received"),AND(F14>0,ABS(J14)>Assumptions!$B$6),AND(G14>0,ABS(K14)>Assumptions!$B$6)),"EXCEPTION","OK") -> EXCEPTION
A15: =Purchase_Orders!A12 -> PO10011 | B15: =Purchase_Orders!B12 -> V1024 | C15: =IFERROR(INDEX(Vendor_Master!$B$2:$B$41,MATCH(B15,Vendor_Master!$A$2:$A$41,0)),"Unknown Vendor") -> Campos Inc | D15: =Purchase_Orders!C12 -> 46192 | E15: =Purchase_Orders!D12 -> 760.24 | F15: =SUMIFS(Goods_Receipt_Notes!$D$2:$D$791,Goods_Receipt_Notes!$B$2:$B$791,A15) -> 760.24 | G15: =SUMIFS(Vendor_Invoices_AP!$E$2:$E$882,Vendor_Invoices_AP!$B$2:$B$882,A15) -> 760.24 | H15: =IF(F15=0,"Not Received","Received") -> Received | I15: =IF(G15=0,"Not Invoiced","Invoiced") -> Invoiced | J15: =E15-F15 -> 0 | K15: =E15-G15 -> 0 | L15: =IF(OR(AND(I15="Invoiced",H15="Not Received"),AND(F15>0,ABS(J15)>Assumptions!$B$6),AND(G15>0,ABS(K15)>Assumptions!$B$6)),"EXCEPTION","OK") -> OK
A16: =Purchase_Orders!A13 -> PO10012 | B16: =Purchase_Orders!B13 -> V1035 | C16: =IFERROR(INDEX(Vendor_Master!$B$2:$B$41,MATCH(B16,Vendor_Master!$A$2:$A$41,0)),"Unknown Vendor") -> Allen PLC | D16: =Purchase_Orders!C13 -> 45950 | E16: =Purchase_Orders!D13 -> 15002.72 | F16: =SUMIFS(Goods_Receipt_Notes!$D$2:$D$791,Goods_Receipt_Notes!$B$2:$B$791,A16) -> 15002.72 | G16: =SUMIFS(Vendor_Invoices_AP!$E$2:$E$882,Vendor_Invoices_AP!$B$2:$B$882,A16) -> 15002.72 | H16: =IF(F16=0,"Not Received","Received") -> Received | I16: =IF(G16=0,"Not Invoiced","Invoiced") -> Invoiced | J16: =E16-F16 -> 0 | K16: =E16-G16 -> 0 | L16: =IF(OR(AND(I16="Invoiced",H16="Not Received"),AND(F16>0,ABS(J16)>Assumptions!$B$6),AND(G16>0,ABS(K16)>Assumptions!$B$6)),"EXCEPTION","OK") -> OK
... A854: =Purchase_Orders!A851 -> PO10850 | B854: =Purchase_Orders!B851 -> V1014 | C854: =IFERROR(INDEX(Vendor_Master!$B$2:$B$41,MATCH(B854,Vendor_Master!$A$2:$A$41,0)),"Unknown Vendor") -> Flowers, Martin and Kelly | D854: =Purchase_Orders!C851 -> 45970 | E854: =Purchase_Orders!D851 -> 4104.49 | F854: =SUMIFS(Goods_Receipt_Notes!$D$2:$D$791,Goods_Receipt_Notes!$B$2:$B$791,A854) -> 4104.49 | G854: =SUMIFS(Vendor_Invoices_AP!$E$2:$E$882,Vendor_Invoices_AP!$B$2:$B$882,A854) -> 4104.49 | H854: =IF(F854=0,"Not Received","Received") -> Received | I854: =IF(G854=0,"Not Invoiced","Invoiced") -> Invoiced | J854: =E854-F854 -> 0 | K854: =E854-G854 -> 0 | L854: =IF(OR(AND(I854="Invoiced",H854="Not Received"),AND(F854>0,ABS(J854)>Assumptions!$B$6),AND(G854>0,ABS(K854)>Assumptions!$B$6)),"EXCEPTION","OK") -> OK

Sheet Bank_Reconciliation
A1: Reconciliation Module 2 — Bank Reconciliation (Payment Log ↔ Bank Statement)
A2: Part A matches every AP payment to the bank statement. Part B (below) finds bank items with no matching payment — timing differences, unexplained fees, or other bank-only activity.
A4: Part A — Payments matched to Bank Statement
A5: Payment_ID | B5: Vendor_ID | C5: Payment_Date | D5: Payment_Amount | E5: Bank_Amount | F5: Bank_Txn_Found | G5: Amount_Diff | H5: Match_Status
A6: =Payment_Log_AP!A2 -> PAY40001 | B6: =Payment_Log_AP!C2 -> V1020 | C6: =Payment_Log_AP!D2 -> 46142 | D6: =Payment_Log_AP!E2 -> 1417.41 | E6: =IFERROR(INDEX(Bank_Statement!$C$2:$C$783,MATCH(A6,Bank_Statement!$E$2:$E$783,0)),"") -> -1417.41 | F6: =IF(E6="","No","Yes") -> Yes | G6: =IF(F6="No","N/A",D6-E6) -> 2834.82 | H6: =IF(F6="No","Unmatched - Investigate",IF(ABS(D6-E6)>Assumptions!$B$6,"Mismatch - Amount Differs","Matched")) -> Mismatch - Amount Differs
A7: =Payment_Log_AP!A3 -> PAY40002 | B7: =Payment_Log_AP!C3 -> V1034 | C7: =Payment_Log_AP!D3 -> 45805 | D7: =Payment_Log_AP!E3 -> 1749.66 | E7: =IFERROR(INDEX(Bank_Statement!$C$2:$C$783,MATCH(A7,Bank_Statement!$E$2:$E$783,0)),"") -> -1749.66 | F7: =IF(E7="","No","Yes") -> Yes | G7: =IF(F7="No","N/A",D7-E7) -> 3499.32 | H7: =IF(F7="No","Unmatched - Investigate",IF(ABS(D7-E7)>Assumptions!$B$6,"Mismatch - Amount Differs","Matched")) -> Mismatch - Amount Differs
A8: =Payment_Log_AP!A4 -> PAY40003 | B8: =Payment_Log_AP!C4 -> V1014 | C8: =Payment_Log_AP!D4 -> 45683 | D8: =Payment_Log_AP!E4 -> 2691.35 | E8: =IFERROR(INDEX(Bank_Statement!$C$2:$C$783,MATCH(A8,Bank_Statement!$E$2:$E$783,0)),"") -> -2691.35 | F8: =IF(E8="","No","Yes") -> Yes | G8: =IF(F8="No","N/A",D8-E8) -> 5382.7 | H8: =IF(F8="No","Unmatched - Investigate",IF(ABS(D8-E8)>Assumptions!$B$6,"Mismatch - Amount Differs","Matched")) -> Mismatch - Amount Differs
A9: =Payment_Log_AP!A5 -> PAY40004 | B9: =Payment_Log_AP!C5 -> V1040 | C9: =Payment_Log_AP!D5 -> 45805 | D9: =Payment_Log_AP!E5 -> 889.24 | E9: =IFERROR(INDEX(Bank_Statement!$C$2:$C$783,MATCH(A9,Bank_Statement!$E$2:$E$783,0)),"") -> -889.24 | F9: =IF(E9="","No","Yes") -> Yes | G9: =IF(F9="No","N/A",D9-E9) -> 1778.48 | H9: =IF(F9="No","Unmatched - Investigate",IF(ABS(D9-E9)>Assumptions!$B$6,"Mismatch - Amount Differs","Matched")) -> Mismatch - Amount Differs
A10: =Payment_Log_AP!A6 -> PAY40005 | B10: =Payment_Log_AP!C6 -> V1022 | C10: =Payment_Log_AP!D6 -> 45883 | D10: =Payment_Log_AP!E6 -> 3058.04 | E10: =IFERROR(INDEX(Bank_Statement!$C$2:$C$783,MATCH(A10,Bank_Statement!$E$2:$E$783,0)),"") -> -3058.04 | F10: =IF(E10="","No","Yes") -> Yes | G10: =IF(F10="No","N/A",D10-E10) -> 6116.08 | H10: =IF(F10="No","Unmatched - Investigate",IF(ABS(D10-E10)>Assumptions!$B$6,"Mismatch - Amount Differs","Matched")) -> Mismatch - Amount Differs
A11: =Payment_Log_AP!A7 -> PAY40006 | B11: =Payment_Log_AP!C7 -> V1040 | C11: =Payment_Log_AP!D7 -> 46160 | D11: =Payment_Log_AP!E7 -> 1359.77 | E11: =IFERROR(INDEX(Bank_Statement!$C$2:$C$783,MATCH(A11,Bank_Statement!$E$2:$E$783,0)),"") -> -1359.77 | F11: =IF(E11="","No","Yes") -> Yes | G11: =IF(F11="No","N/A",D11-E11) -> 2719.54 | H11: =IF(F11="No","Unmatched - Investigate",IF(ABS(D11-E11)>Assumptions!$B$6,"Mismatch - Amount Differs","Matched")) -> Mismatch - Amount Differs
A12: =Payment_Log_AP!A8 -> PAY40007 | B12: =Payment_Log_AP!C8 -> V1040 | C12: =Payment_Log_AP!D8 -> 46193 | D12: =Payment_Log_AP!E8 -> 3708.39 | E12: =IFERROR(INDEX(Bank_Statement!$C$2:$C$783,MATCH(A12,Bank_Statement!$E$2:$E$783,0)),"") -> -3708.39 | F12: =IF(E12="","No","Yes") -> Yes | G12: =IF(F12="No","N/A",D12-E12) -> 7416.78 | H12: =IF(F12="No","Unmatched - Investigate",IF(ABS(D12-E12)>Assumptions!$B$6,"Mismatch - Amount Differs","Matched")) -> Mismatch - Amount Differs
A13: =Payment_Log_AP!A9 -> PAY40008 | B13: =Payment_Log_AP!C9 -> V1015 | C13: =Payment_Log_AP!D9 -> 45859 | D13: =Payment_Log_AP!E9 -> 6081.19 | E13: =IFERROR(INDEX(Bank_Statement!$C$2:$C$783,MATCH(A13,Bank_Statement!$E$2:$E$783,0)),"") -> -6081.19 | F13: =IF(E13="","No","Yes") -> Yes | G13: =IF(F13="No","N/A",D13-E13) -> 12162.38 | H13: =IF(F13="No","Unmatched - Investigate",IF(ABS(D13-E13)>Assumptions!$B$6,"Mismatch - Amount Differs","Matched")) -> Mismatch - Amount Differs
A14: =Payment_Log_AP!A10 -> PAY40009 | B14: =Payment_Log_AP!C10 -> V1005 | C14: =Payment_Log_AP!D10 -> 45885 | D14: =Payment_Log_AP!E10 -> 1466.07 | E14: =IFERROR(INDEX(Bank_Statement!$C$2:$C$783,MATCH(A14,Bank_Statement!$E$2:$E$783,0)),"") -> -1466.07 | F14: =IF(E14="","No","Yes") -> Yes | G14: =IF(F14="No","N/A",D14-E14) -> 2932.14 | H14: =IF(F14="No","Unmatched - Investigate",IF(ABS(D14-E14)>Assumptions!$B$6,"Mismatch - Amount Differs","Matched")) -> Mismatch - Amount Differs
A15: =Payment_Log_AP!A11 -> PAY40010 | B15: =Payment_Log_AP!C11 -> V1035 | C15: =Payment_Log_AP!D11 -> 45989 | D15: =Payment_Log_AP!E11 -> 15002.72 | E15: =IFERROR(INDEX(Bank_Statement!$C$2:$C$783,MATCH(A15,Bank_Statement!$E$2:$E$783,0)),"") -> -15002.72 | F15: =IF(E15="","No","Yes") -> Yes | G15: =IF(F15="No","N/A",D15-E15) -> 30005.44 | H15: =IF(F15="No","Unmatched - Investigate",IF(ABS(D15-E15)>Assumptions!$B$6,"Mismatch - Amount Differs","Matched")) -> Mismatch - Amount Differs
A16: =Payment_Log_AP!A12 -> PAY40011 | B16: =Payment_Log_AP!C12 -> V1016 | C16: =Payment_Log_AP!D12 -> 46196 | D16: =Payment_Log_AP!E12 -> 911.91 | E16: =IFERROR(INDEX(Bank_Statement!$C$2:$C$783,MATCH(A16,Bank_Statement!$E$2:$E$783,0)),"") -> -911.91 | F16: =IF(E16="","No","Yes") -> Yes | G16: =IF(F16="No","N/A",D16-E16) -> 1823.82 | H16: =IF(F16="No","Unmatched - Investigate",IF(ABS(D16-E16)>Assumptions!$B$6,"Mismatch - Amount Differs","Matched")) -> Mismatch - Amount Differs
A17: =Payment_Log_AP!A13 -> PAY40012 | B17: =Payment_Log_AP!C13 -> V1002 | C17: =Payment_Log_AP!D13 -> 45753 | D17: =Payment_Log_AP!E13 -> 1222.88 | E17: =IFERROR(INDEX(Bank_Statement!$C$2:$C$783,MATCH(A17,Bank_Statement!$E$2:$E$783,0)),"") -> -1222.88 | F17: =IF(E17="","No","Yes") -> Yes | G17: =IF(F17="No","N/A",D17-E17) -> 2445.76 | H17: =IF(F17="No","Unmatched - Investigate",IF(ABS(D17-E17)>Assumptions!$B$6,"Mismatch - Amount Differs","Matched")) -> Mismatch - Amount Differs
... A757: =Payment_Log_AP!A753 -> PAY40752 | B757: =Payment_Log_AP!C753 -> V1014 | C757: =Payment_Log_AP!D753 -> 46002 | D757: =Payment_Log_AP!E753 -> 4104.49 | E757: =IFERROR(INDEX(Bank_Statement!$C$2:$C$783,MATCH(A757,Bank_Statement!$E$2:$E$783,0)),"") -> -4104.49 | F757: =IF(E757="","No","Yes") -> Yes | G757: =IF(F757="No","N/A",D757-E757) -> 8208.98 | H757: =IF(F757="No","Unmatched - Investigate",IF(ABS(D757-E757)>Assumptions!$B$6,"Mismatch - Amount Differs","Matched")) -> Mismatch - Amount Differs
A760: Part B — Bank Statement items matched back to Payments
A761: Bank_Txn_ID | B761: Date | C761: Amount | D761: Description | E761: Matched_Payment_ID | F761: Ref_Found_In_AP_Log | G761: Status
A762: =Bank_Statement!A2 -> BNK50001 | B762: =Bank_Statement!B2 -> 46144 | C762: =Bank_Statement!C2 -> -1417.41 | D762: =Bank_Statement!D2 -> PMT-V1020 | E762: =Bank_Statement!E2 -> PAY40001 | F762: =IF(E762="","N/A",IF(COUNTIF(Payment_Log_AP!$A$2:$A$753,E762)>0,"Yes","No")) -> Yes | G762: =IF(E762="","Unexplained Bank Item (fee/other - review)",IF(F762="Yes","Matched","Payment Reference Not Found in AP Log")) -> Matched
A763: =Bank_Statement!A3 -> BNK50002 | B763: =Bank_Statement!B3 -> 45807 | C763: =Bank_Statement!C3 -> -1749.66 | D763: =Bank_Statement!D3 -> PMT-V1034 | E763: =Bank_Statement!E3 -> PAY40002 | F763: =IF(E763="","N/A",IF(COUNTIF(Payment_Log_AP!$A$2:$A$753,E763)>0,"Yes","No")) -> Yes | G763: =IF(E763="","Unexplained Bank Item (fee/other - review)",IF(F763="Yes","Matched","Payment Reference Not Found in AP Log")) -> Matched
A764: =Bank_Statement!A4 -> BNK50003 | B764: =Bank_Statement!B4 -> 45683 | C764: =Bank_Statement!C4 -> -2691.35 | D764: =Bank_Statement!D4 -> PMT-V1014 | E764: =Bank_Statement!E4 -> PAY40003 | F764: =IF(E764="","N/A",IF(COUNTIF(Payment_Log_AP!$A$2:$A$753,E764)>0,"Yes","No")) -> Yes | G764: =IF(E764="","Unexplained Bank Item (fee/other - review)",IF(F764="Yes","Matched","Payment Reference Not Found in AP Log")) -> Matched
A765: =Bank_Statement!A5 -> BNK50004 | B765: =Bank_Statement!B5 -> 45808 | C765: =Bank_Statement!C5 -> -889.24 | D765: =Bank_Statement!D5 -> PMT-V1040 | E765: =Bank_Statement!E5 -> PAY40004 | F765: =IF(E765="","N/A",IF(COUNTIF(Payment_Log_AP!$A$2:$A$753,E765)>0,"Yes","No")) -> Yes | G765: =IF(E765="","Unexplained Bank Item (fee/other - review)",IF(F765="Yes","Matched","Payment Reference Not Found in AP Log")) -> Matched
A766: =Bank_Statement!A6 -> BNK50005 | B766: =Bank_Statement!B6 -> 45886 | C766: =Bank_Statement!C6 -> -3058.04 | D766: =Bank_Statement!D6 -> PMT-V1022 | E766: =Bank_Statement!E6 -> PAY40005 | F766: =IF(E766="","N/A",IF(COUNTIF(Payment_Log_AP!$A$2:$A$753,E766)>0,"Yes","No")) -> Yes | G766: =IF(E766="","Unexplained Bank Item (fee/other - review)",IF(F766="Yes","Matched","Payment Reference Not Found in AP Log")) -> Matched
A767: =Bank_Statement!A7 -> BNK50006 | B767: =Bank_Statement!B7 -> 46161 | C767: =Bank_Statement!C7 -> -1359.77 | D767: =Bank_Statement!D7 -> PMT-V1040 | E767: =Bank_Statement!E7 -> PAY40006 | F767: =IF(E767="","N/A",IF(COUNTIF(Payment_Log_AP!$A$2:$A$753,E767)>0,"Yes","No")) -> Yes | G767: =IF(E767="","Unexplained Bank Item (fee/other - review)",IF(F767="Yes","Matched","Payment Reference Not Found in AP Log")) -> Matched
A768: =Bank_Statement!A8 -> BNK50007 | B768: =Bank_Statement!B8 -> 46195 | C768: =Bank_Statement!C8 -> -3708.39 | D768: =Bank_Statement!D8 -> PMT-V1040 | E768: =Bank_Statement!E8 -> PAY40007 | F768: =IF(E768="","N/A",IF(COUNTIF(Payment_Log_AP!$A$2:$A$753,E768)>0,"Yes","No")) -> Yes | G768: =IF(E768="","Unexplained Bank Item (fee/other - review)",IF(F768="Yes","Matched","Payment Reference Not Found in AP Log")) -> Matched
A769: =Bank_Statement!A9 -> BNK50008 | B769: =Bank_Statement!B9 -> 45861 | C769: =Bank_Statement!C9 -> -6081.19 | D769: =Bank_Statement!D9 -> PMT-V1015 | E769: =Bank_Statement!E9 -> PAY40008 | F769: =IF(E769="","N/A",IF(COUNTIF(Payment_Log_AP!$A$2:$A$753,E769)>0,"Yes","No")) -> Yes | G769: =IF(E769="","Unexplained Bank Item (fee/other - review)",IF(F769="Yes","Matched","Payment Reference Not Found in AP Log")) -> Matched
A770: =Bank_Statement!A10 -> BNK50009 | B770: =Bank_Statement!B10 -> 45885 | C770: =Bank_Statement!C10 -> -1466.07 | D770: =Bank_Statement!D10 -> PMT-V1005 | E770: =Bank_Statement!E10 -> PAY40009 | F770: =IF(E770="","N/A",IF(COUNTIF(Payment_Log_AP!$A$2:$A$753,E770)>0,"Yes","No")) -> Yes | G770: =IF(E770="","Unexplained Bank Item (fee/other - review)",IF(F770="Yes","Matched","Payment Reference Not Found in AP Log")) -> Matched
A771: =Bank_Statement!A11 -> BNK50010 | B771: =Bank_Statement!B11 -> 45992 | C771: =Bank_Statement!C11 -> -15002.72 | D771: =Bank_Statement!D11 -> PMT-V1035 | E771: =Bank_Statement!E11 -> PAY40010 | F771: =IF(E771="","N/A",IF(COUNTIF(Payment_Log_AP!$A$2:$A$753,E771)>0,"Yes","No")) -> Yes | G771: =IF(E771="","Unexplained Bank Item (fee/other - review)",IF(F771="Yes","Matched","Payment Reference Not Found in AP Log")) -> Matched
A772: =Bank_Statement!A12 -> BNK50011 | B772: =Bank_Statement!B12 -> 46197 | C772: =Bank_Statement!C12 -> -911.91 | D772: =Bank_Statement!D12 -> PMT-V1016 | E772: =Bank_Statement!E12 -> PAY40011 | F772: =IF(E772="","N/A",IF(COUNTIF(Payment_Log_AP!$A$2:$A$753,E772)>0,"Yes","No")) -> Yes | G772: =IF(E772="","Unexplained Bank Item (fee/other - review)",IF(F772="Yes","Matched","Payment Reference Not Found in AP Log")) -> Matched
A773: =Bank_Statement!A13 -> BNK50012 | B773: =Bank_Statement!B13 -> 45753 | C773: =Bank_Statement!C13 -> -1222.88 | D773: =Bank_Statement!D13 -> PMT-V1002 | E773: =Bank_Statement!E13 -> PAY40012 | F773: =IF(E773="","N/A",IF(COUNTIF(Payment_Log_AP!$A$2:$A$753,E773)>0,"Yes","No")) -> Yes | G773: =IF(E773="","Unexplained Bank Item (fee/other - review)",IF(F773="Yes","Matched","Payment Reference Not Found in AP Log")) -> Matched
... A1543: =Bank_Statement!A783 -> BNK50782 | B1543: =Bank_Statement!B783 -> 45765 | C1543: =Bank_Statement!C783 -> -475.97 | D1543: =Bank_Statement!D783 -> Bank Service Charge | E1543: =Bank_Statement!E783 -> 0 | F1543: =IF(E1543="","N/A",IF(COUNTIF(Payment_Log_AP!$A$2:$A$753,E1543)>0,"Yes","No")) -> N/A | G1543: =IF(E1543="","Unexplained Bank Item (fee/other - review)",IF(F1543="Yes","Matched","Payment Reference Not Found in AP Log")) -> Unexplained Bank Item (fee/other - review)

Sheet AP_Aging
A1: Accounts Payable — Aging
A2: Base table: Vendor_Invoices_AP. Buckets outstanding balances as of Assumptions!B5.
A4: Invoice_ID | B4: Vendor_ID | C4: Vendor_Name | D4: Invoice_Date | E4: Due_Date | F4: Invoice_Amount | G4: Paid_Amount | H4: Outstanding_Balance | I4: Days_Outstanding | J4: Aging_Bucket | K4: Status
A5: =Vendor_Invoices_AP!A2 -> INV30001 | B5: =Vendor_Invoices_AP!C2 -> V1020 | C5: =IFERROR(INDEX(Vendor_Master!$B$2:$B$41,MATCH(B5,Vendor_Master!$A$2:$A$41,0)),"Unknown Vendor") -> Lewis-Porter | D5: =Vendor_Invoices_AP!D2 -> 46109 | E5: =Vendor_Invoices_AP!F2 -> 46139 | F5: =Vendor_Invoices_AP!E2 -> 1417.41 | G5: =SUMIFS(Payment_Log_AP!$E$2:$E$753,Payment_Log_AP!$B$2:$B$753,A5) -> 1417.41 | H5: =F5-G5 -> 0 | I5: =IF(H5<=0.01,0,MAX(Assumptions!$B$5-E5,0)) -> 0 | J5: =IF(H5<=0.01,"Paid",IF(I5<=30,"0-30",IF(I5<=60,"31-60",IF(I5<=90,"61-90","90+")))) -> Paid | K5: =IF(H5<=0.01,"Paid",IF(G5>0,"Partially Paid","Unpaid")) -> Paid
A6: =Vendor_Invoices_AP!A3 -> INV30002 | B6: =Vendor_Invoices_AP!C3 -> V1034 | C6: =IFERROR(INDEX(Vendor_Master!$B$2:$B$41,MATCH(B6,Vendor_Master!$A$2:$A$41,0)),"Unknown Vendor") -> Koch-Decker | D6: =Vendor_Invoices_AP!D3 -> 45803 | E6: =Vendor_Invoices_AP!F3 -> 45848 | F6: =Vendor_Invoices_AP!E3 -> 1749.66 | G6: =SUMIFS(Payment_Log_AP!$E$2:$E$753,Payment_Log_AP!$B$2:$B$753,A6) -> 1749.66 | H6: =F6-G6 -> 0 | I6: =IF(H6<=0.01,0,MAX(Assumptions!$B$5-E6,0)) -> 0 | J6: =IF(H6<=0.01,"Paid",IF(I6<=30,"0-30",IF(I6<=60,"31-60",IF(I6<=90,"61-90","90+")))) -> Paid | K6: =IF(H6<=0.01,"Paid",IF(G6>0,"Partially Paid","Unpaid")) -> Paid
A7: =Vendor_Invoices_AP!A4 -> INV30003 | B7: =Vendor_Invoices_AP!C4 -> V1014 | C7: =IFERROR(INDEX(Vendor_Master!$B$2:$B$41,MATCH(B7,Vendor_Master!$A$2:$A$41,0)),"Unknown Vendor") -> Flowers, Martin and Kelly | D7: =Vendor_Invoices_AP!D4 -> 45676 | E7: =Vendor_Invoices_AP!F4 -> 45706 | F7: =Vendor_Invoices_AP!E4 -> 2691.35 | G7: =SUMIFS(Payment_Log_AP!$E$2:$E$753,Payment_Log_AP!$B$2:$B$753,A7) -> 2691.35 | H7: =F7-G7 -> 0 | I7: =IF(H7<=0.01,0,MAX(Assumptions!$B$5-E7,0)) -> 0 | J7: =IF(H7<=0.01,"Paid",IF(I7<=30,"0-30",IF(I7<=60,"31-60",IF(I7<=90,"61-90","90+")))) -> Paid | K7: =IF(H7<=0.01,"Paid",IF(G7>0,"Partially Paid","Unpaid")) -> Paid
A8: =Vendor_Invoices_AP!A5 -> INV30004 | B8: =Vendor_Invoices_AP!C5 -> V1040 | C8: =IFERROR(INDEX(Vendor_Master!$B$2:$B$41,MATCH(B8,Vendor_Master!$A$2:$A$41,0)),"Unknown Vendor") -> Santos, Kim and Holmes | D8: =Vendor_Invoices_AP!D5 -> 45783 | E8: =Vendor_Invoices_AP!F5 -> 45798 | F8: =Vendor_Invoices_AP!E5 -> 889.24 | G8: =SUMIFS(Payment_Log_AP!$E$2:$E$753,Payment_Log_AP!$B$2:$B$753,A8) -> 889.24 | H8: =F8-G8 -> 0 | I8: =IF(H8<=0.01,0,MAX(Assumptions!$B$5-E8,0)) -> 0 | J8: =IF(H8<=0.01,"Paid",IF(I8<=30,"0-30",IF(I8<=60,"31-60",IF(I8<=90,"61-90","90+")))) -> Paid | K8: =IF(H8<=0.01,"Paid",IF(G8>0,"Partially Paid","Unpaid")) -> Paid
A9: =Vendor_Invoices_AP!A6 -> INV30005 | B9: =Vendor_Invoices_AP!C6 -> V1022 | C9: =IFERROR(INDEX(Vendor_Master!$B$2:$B$41,MATCH(B9,Vendor_Master!$A$2:$A$41,0)),"Unknown Vendor") -> Burgess-Patterson | D9: =Vendor_Invoices_AP!D6 -> 45861 | E9: =Vendor_Invoices_AP!F6 -> 45891 | F9: =Vendor_Invoices_AP!E6 -> 3058.04 | G9: =SUMIFS(Payment_Log_AP!$E$2:$E$753,Payment_Log_AP!$B$2:$B$753,A9) -> 3058.04 | H9: =F9-G9 -> 0 | I9: =IF(H9<=0.01,0,MAX(Assumptions!$B$5-E9,0)) -> 0 | J9: =IF(H9<=0.01,"Paid",IF(I9<=30,"0-30",IF(I9<=60,"31-60",IF(I9<=90,"61-90","90+")))) -> Paid | K9: =IF(H9<=0.01,"Paid",IF(G9>0,"Partially Paid","Unpaid")) -> Paid
A10: =Vendor_Invoices_AP!A7 -> INV30006 | B10: =Vendor_Invoices_AP!C7 -> V1040 | C10: =IFERROR(INDEX(Vendor_Master!$B$2:$B$41,MATCH(B10,Vendor_Master!$A$2:$A$41,0)),"Unknown Vendor") -> Santos, Kim and Holmes | D10: =Vendor_Invoices_AP!D7 -> 46132 | E10: =Vendor_Invoices_AP!F7 -> 46147 | F10: =Vendor_Invoices_AP!E7 -> 1359.77 | G10: =SUMIFS(Payment_Log_AP!$E$2:$E$753,Payment_Log_AP!$B$2:$B$753,A10) -> 1359.77 | H10: =F10-G10 -> 0 | I10: =IF(H10<=0.01,0,MAX(Assumptions!$B$5-E10,0)) -> 0 | J10: =IF(H10<=0.01,"Paid",IF(I10<=30,"0-30",IF(I10<=60,"31-60",IF(I10<=90,"61-90","90+")))) -> Paid | K10: =IF(H10<=0.01,"Paid",IF(G10>0,"Partially Paid","Unpaid")) -> Paid
A11: =Vendor_Invoices_AP!A8 -> INV30007 | B11: =Vendor_Invoices_AP!C8 -> V1040 | C11: =IFERROR(INDEX(Vendor_Master!$B$2:$B$41,MATCH(B11,Vendor_Master!$A$2:$A$41,0)),"Unknown Vendor") -> Santos, Kim and Holmes | D11: =Vendor_Invoices_AP!D8 -> 46188 | E11: =Vendor_Invoices_AP!F8 -> 46203 | F11: =Vendor_Invoices_AP!E8 -> 3708.39 | G11: =SUMIFS(Payment_Log_AP!$E$2:$E$753,Payment_Log_AP!$B$2:$B$753,A11) -> 3708.39 | H11: =F11-G11 -> 0 | I11: =IF(H11<=0.01,0,MAX(Assumptions!$B$5-E11,0)) -> 0 | J11: =IF(H11<=0.01,"Paid",IF(I11<=30,"0-30",IF(I11<=60,"31-60",IF(I11<=90,"61-90","90+")))) -> Paid | K11: =IF(H11<=0.01,"Paid",IF(G11>0,"Partially Paid","Unpaid")) -> Paid
A12: =Vendor_Invoices_AP!A9 -> INV30008 | B12: =Vendor_Invoices_AP!C9 -> V1015 | C12: =IFERROR(INDEX(Vendor_Master!$B$2:$B$41,MATCH(B12,Vendor_Master!$A$2:$A$41,0)),"Unknown Vendor") -> Zuniga, Wong and Lynch | D12: =Vendor_Invoices_AP!D9 -> 45833 | E12: =Vendor_Invoices_AP!F9 -> 45863 | F12: =Vendor_Invoices_AP!E9 -> 6081.19 | G12: =SUMIFS(Payment_Log_AP!$E$2:$E$753,Payment_Log_AP!$B$2:$B$753,A12) -> 6081.19 | H12: =F12-G12 -> 0 | I12: =IF(H12<=0.01,0,MAX(Assumptions!$B$5-E12,0)) -> 0 | J12: =IF(H12<=0.01,"Paid",IF(I12<=30,"0-30",IF(I12<=60,"31-60",IF(I12<=90,"61-90","90+")))) -> Paid | K12: =IF(H12<=0.01,"Paid",IF(G12>0,"Partially Paid","Unpaid")) -> Paid
A13: =Vendor_Invoices_AP!A10 -> INV30009 | B13: =Vendor_Invoices_AP!C10 -> V1018 | C13: =IFERROR(INDEX(Vendor_Master!$B$2:$B$41,MATCH(B13,Vendor_Master!$A$2:$A$41,0)),"Unknown Vendor") -> Underwood LLC | D13: =Vendor_Invoices_AP!D10 -> 46020 | E13: =Vendor_Invoices_AP!F10 -> 46050 | F13: =Vendor_Invoices_AP!E10 -> 6038.81 | G13: =SUMIFS(Payment_Log_AP!$E$2:$E$753,Payment_Log_AP!$B$2:$B$753,A13) -> 0 | H13: =F13-G13 -> 6038.81 | I13: =IF(H13<=0.01,0,MAX(Assumptions!$B$5-E13,0)) -> 184 | J13: =IF(H13<=0.01,"Paid",IF(I13<=30,"0-30",IF(I13<=60,"31-60",IF(I13<=90,"61-90","90+")))) -> 90+ | K13: =IF(H13<=0.01,"Paid",IF(G13>0,"Partially Paid","Unpaid")) -> Unpaid
A14: =Vendor_Invoices_AP!A11 -> INV30010 | B14: =Vendor_Invoices_AP!C11 -> V1005 | C14: =IFERROR(INDEX(Vendor_Master!$B$2:$B$41,MATCH(B14,Vendor_Master!$A$2:$A$41,0)),"Unknown Vendor") -> Cole LLC | D14: =Vendor_Invoices_AP!D11 -> 45878 | E14: =Vendor_Invoices_AP!F11 -> 45893 | F14: =Vendor_Invoices_AP!E11 -> 1466.07 | G14: =SUMIFS(Payment_Log_AP!$E$2:$E$753,Payment_Log_AP!$B$2:$B$753,A14) -> 1466.07 | H14: =F14-G14 -> 0 | I14: =IF(H14<=0.01,0,MAX(Assumptions!$B$5-E14,0)) -> 0 | J14: =IF(H14<=0.01,"Paid",IF(I14<=30,"0-30",IF(I14<=60,"31-60",IF(I14<=90,"61-90","90+")))) -> Paid | K14: =IF(H14<=0.01,"Paid",IF(G14>0,"Partially Paid","Unpaid")) -> Paid
A15: =Vendor_Invoices_AP!A12 -> INV30011 | B15: =Vendor_Invoices_AP!C12 -> V1024 | C15: =IFERROR(INDEX(Vendor_Master!$B$2:$B$41,MATCH(B15,Vendor_Master!$A$2:$A$41,0)),"Unknown Vendor") -> Campos Inc | D15: =Vendor_Invoices_AP!D12 -> 46210 | E15: =Vendor_Invoices_AP!F12 -> 46270 | F15: =Vendor_Invoices_AP!E12 -> 760.24 | G15: =SUMIFS(Payment_Log_AP!$E$2:$E$753,Payment_Log_AP!$B$2:$B$753,A15) -> 0 | H15: =F15-G15 -> 760.24 | I15: =IF(H15<=0.01,0,MAX(Assumptions!$B$5-E15,0)) -> 0 | J15: =IF(H15<=0.01,"Paid",IF(I15<=30,"0-30",IF(I15<=60,"31-60",IF(I15<=90,"61-90","90+")))) -> 0-30 | K15: =IF(H15<=0.01,"Paid",IF(G15>0,"Partially Paid","Unpaid")) -> Unpaid
A16: =Vendor_Invoices_AP!A13 -> INV30012 | B16: =Vendor_Invoices_AP!C13 -> V1035 | C16: =IFERROR(INDEX(Vendor_Master!$B$2:$B$41,MATCH(B16,Vendor_Master!$A$2:$A$41,0)),"Unknown Vendor") -> Allen PLC | D16: =Vendor_Invoices_AP!D13 -> 45975 | E16: =Vendor_Invoices_AP!F13 -> 45990 | F16: =Vendor_Invoices_AP!E13 -> 15002.72 | G16: =SUMIFS(Payment_Log_AP!$E$2:$E$753,Payment_Log_AP!$B$2:$B$753,A16) -> 15002.72 | H16: =F16-G16 -> 0 | I16: =IF(H16<=0.01,0,MAX(Assumptions!$B$5-E16,0)) -> 0 | J16: =IF(H16<=0.01,"Paid",IF(I16<=30,"0-30",IF(I16<=60,"31-60",IF(I16<=90,"61-90","90+")))) -> Paid | K16: =IF(H16<=0.01,"Paid",IF(G16>0,"Partially Paid","Unpaid")) -> Paid
... A885: =Vendor_Invoices_AP!A882 -> INV30881 | B885: =Vendor_Invoices_AP!C882 -> V1014 | C885: =IFERROR(INDEX(Vendor_Master!$B$2:$B$41,MATCH(B885,Vendor_Master!$A$2:$A$41,0)),"Unknown Vendor") -> Flowers, Martin and Kelly | D885: =Vendor_Invoices_AP!D882 -> 45973 | E885: =Vendor_Invoices_AP!F882 -> 46003 | F885: =Vendor_Invoices_AP!E882 -> 4104.49 | G885: =SUMIFS(Payment_Log_AP!$E$2:$E$753,Payment_Log_AP!$B$2:$B$753,A885) -> 4104.49 | H885: =F885-G885 -> 0 | I885: =IF(H885<=0.01,0,MAX(Assumptions!$B$5-E885,0)) -> 0 | J885: =IF(H885<=0.01,"Paid",IF(I885<=30,"0-30",IF(I885<=60,"31-60",IF(I885<=90,"61-90","90+")))) -> Paid | K885: =IF(H885<=0.01,"Paid",IF(G885>0,"Partially Paid","Unpaid")) -> Paid
A888: AP Aging Summary (as of Assumptions!B5)
A889: Bucket | B889: Outstanding $ | C889: Invoice Count
A890: 0-30 | B890: =SUMIFS($H$5:$H$885,$J$5:$J$885,A890) -> 248495.64 | C890: =COUNTIFS($J$5:$J$885,A890) -> 48
A891: 31-60 | B891: =SUMIFS($H$5:$H$885,$J$5:$J$885,A891) -> 15605.37 | C891: =COUNTIFS($J$5:$J$885,A891) -> 7
A892: 61-90 | B892: =SUMIFS($H$5:$H$885,$J$5:$J$885,A892) -> 24163.94 | C892: =COUNTIFS($J$5:$J$885,A892) -> 8
A893: 90+ | B893: =SUMIFS($H$5:$H$885,$J$5:$J$885,A893) -> 281252.27 | C893: =COUNTIFS($J$5:$J$885,A893) -> 82

Sheet Duplicate_Payments
A1: Accounts Payable — Duplicate Payment Detection
A2: Base table: Vendor_Invoices_AP (one row per invoice). Counts how many payments in Payment_Log_AP reference each invoice.
A4: Invoice_ID | B4: Vendor_ID | C4: Vendor_Name | D4: Invoice_Amount | E4: Payment_Count | F4: Total_Paid | G4: Overpayment_Amount | H4: Flag
A5: =Vendor_Invoices_AP!A2 -> INV30001 | B5: =Vendor_Invoices_AP!C2 -> V1020 | C5: =IFERROR(INDEX(Vendor_Master!$B$2:$B$41,MATCH(B5,Vendor_Master!$A$2:$A$41,0)),"Unknown Vendor") -> Lewis-Porter | D5: =Vendor_Invoices_AP!E2 -> 1417.41 | E5: =COUNTIF(Payment_Log_AP!$B$2:$B$753,A5) -> 1 | F5: =SUMIFS(Payment_Log_AP!$E$2:$E$753,Payment_Log_AP!$B$2:$B$753,A5) -> 1417.41 | G5: =MAX(F5-D5,0) -> 0 | H5: =IF(E5>1,"DUPLICATE - Review",IF(G5>Assumptions!$B$6,"OVERPAID - Review","OK")) -> OK
A6: =Vendor_Invoices_AP!A3 -> INV30002 | B6: =Vendor_Invoices_AP!C3 -> V1034 | C6: =IFERROR(INDEX(Vendor_Master!$B$2:$B$41,MATCH(B6,Vendor_Master!$A$2:$A$41,0)),"Unknown Vendor") -> Koch-Decker | D6: =Vendor_Invoices_AP!E3 -> 1749.66 | E6: =COUNTIF(Payment_Log_AP!$B$2:$B$753,A6) -> 1 | F6: =SUMIFS(Payment_Log_AP!$E$2:$E$753,Payment_Log_AP!$B$2:$B$753,A6) -> 1749.66 | G6: =MAX(F6-D6,0) -> 0 | H6: =IF(E6>1,"DUPLICATE - Review",IF(G6>Assumptions!$B$6,"OVERPAID - Review","OK")) -> OK
A7: =Vendor_Invoices_AP!A4 -> INV30003 | B7: =Vendor_Invoices_AP!C4 -> V1014 | C7: =IFERROR(INDEX(Vendor_Master!$B$2:$B$41,MATCH(B7,Vendor_Master!$A$2:$A$41,0)),"Unknown Vendor") -> Flowers, Martin and Kelly | D7: =Vendor_Invoices_AP!E4 -> 2691.35 | E7: =COUNTIF(Payment_Log_AP!$B$2:$B$753,A7) -> 1 | F7: =SUMIFS(Payment_Log_AP!$E$2:$E$753,Payment_Log_AP!$B$2:$B$753,A7) -> 2691.35 | G7: =MAX(F7-D7,0) -> 0 | H7: =IF(E7>1,"DUPLICATE - Review",IF(G7>Assumptions!$B$6,"OVERPAID - Review","OK")) -> OK
A8: =Vendor_Invoices_AP!A5 -> INV30004 | B8: =Vendor_Invoices_AP!C5 -> V1040 | C8: =IFERROR(INDEX(Vendor_Master!$B$2:$B$41,MATCH(B8,Vendor_Master!$A$2:$A$41,0)),"Unknown Vendor") -> Santos, Kim and Holmes | D8: =Vendor_Invoices_AP!E5 -> 889.24 | E8: =COUNTIF(Payment_Log_AP!$B$2:$B$753,A8) -> 1 | F8: =SUMIFS(Payment_Log_AP!$E$2:$E$753,Payment_Log_AP!$B$2:$B$753,A8) -> 889.24 | G8: =MAX(F8-D8,0) -> 0 | H8: =IF(E8>1,"DUPLICATE - Review",IF(G8>Assumptions!$B$6,"OVERPAID - Review","OK")) -> OK
A9: =Vendor_Invoices_AP!A6 -> INV30005 | B9: =Vendor_Invoices_AP!C6 -> V1022 | C9: =IFERROR(INDEX(Vendor_Master!$B$2:$B$41,MATCH(B9,Vendor_Master!$A$2:$A$41,0)),"Unknown Vendor") -> Burgess-Patterson | D9: =Vendor_Invoices_AP!E6 -> 3058.04 | E9: =COUNTIF(Payment_Log_AP!$B$2:$B$753,A9) -> 1 | F9: =SUMIFS(Payment_Log_AP!$E$2:$E$753,Payment_Log_AP!$B$2:$B$753,A9) -> 3058.04 | G9: =MAX(F9-D9,0) -> 0 | H9: =IF(E9>1,"DUPLICATE - Review",IF(G9>Assumptions!$B$6,"OVERPAID - Review","OK")) -> OK
A10: =Vendor_Invoices_AP!A7 -> INV30006 | B10: =Vendor_Invoices_AP!C7 -> V1040 | C10: =IFERROR(INDEX(Vendor_Master!$B$2:$B$41,MATCH(B10,Vendor_Master!$A$2:$A$41,0)),"Unknown Vendor") -> Santos, Kim and Holmes | D10: =Vendor_Invoices_AP!E7 -> 1359.77 | E10: =COUNTIF(Payment_Log_AP!$B$2:$B$753,A10) -> 1 | F10: =SUMIFS(Payment_Log_AP!$E$2:$E$753,Payment_Log_AP!$B$2:$B$753,A10) -> 1359.77 | G10: =MAX(F10-D10,0) -> 0 | H10: =IF(E10>1,"DUPLICATE - Review",IF(G10>Assumptions!$B$6,"OVERPAID - Review","OK")) -> OK
A11: =Vendor_Invoices_AP!A8 -> INV30007 | B11: =Vendor_Invoices_AP!C8 -> V1040 | C11: =IFERROR(INDEX(Vendor_Master!$B$2:$B$41,MATCH(B11,Vendor_Master!$A$2:$A$41,0)),"Unknown Vendor") -> Santos, Kim and Holmes | D11: =Vendor_Invoices_AP!E8 -> 3708.39 | E11: =COUNTIF(Payment_Log_AP!$B$2:$B$753,A11) -> 1 | F11: =SUMIFS(Payment_Log_AP!$E$2:$E$753,Payment_Log_AP!$B$2:$B$753,A11) -> 3708.39 | G11: =MAX(F11-D11,0) -> 0 | H11: =IF(E11>1,"DUPLICATE - Review",IF(G11>Assumptions!$B$6,"OVERPAID - Review","OK")) -> OK
A12: =Vendor_Invoices_AP!A9 -> INV30008 | B12: =Vendor_Invoices_AP!C9 -> V1015 | C12: =IFERROR(INDEX(Vendor_Master!$B$2:$B$41,MATCH(B12,Vendor_Master!$A$2:$A$41,0)),"Unknown Vendor") -> Zuniga, Wong and Lynch | D12: =Vendor_Invoices_AP!E9 -> 6081.19 | E12: =COUNTIF(Payment_Log_AP!$B$2:$B$753,A12) -> 1 | F12: =SUMIFS(Payment_Log_AP!$E$2:$E$753,Payment_Log_AP!$B$2:$B$753,A12) -> 6081.19 | G12: =MAX(F12-D12,0) -> 0 | H12: =IF(E12>1,"DUPLICATE - Review",IF(G12>Assumptions!$B$6,"OVERPAID - Review","OK")) -> OK
A13: =Vendor_Invoices_AP!A10 -> INV30009 | B13: =Vendor_Invoices_AP!C10 -> V1018 | C13: =IFERROR(INDEX(Vendor_Master!$B$2:$B$41,MATCH(B13,Vendor_Master!$A$2:$A$41,0)),"Unknown Vendor") -> Underwood LLC | D13: =Vendor_Invoices_AP!E10 -> 6038.81 | E13: =COUNTIF(Payment_Log_AP!$B$2:$B$753,A13) -> 0 | F13: =SUMIFS(Payment_Log_AP!$E$2:$E$753,Payment_Log_AP!$B$2:$B$753,A13) -> 0 | G13: =MAX(F13-D13,0) -> 0 | H13: =IF(E13>1,"DUPLICATE - Review",IF(G13>Assumptions!$B$6,"OVERPAID - Review","OK")) -> OK
A14: =Vendor_Invoices_AP!A11 -> INV30010 | B14: =Vendor_Invoices_AP!C11 -> V1005 | C14: =IFERROR(INDEX(Vendor_Master!$B$2:$B$41,MATCH(B14,Vendor_Master!$A$2:$A$41,0)),"Unknown Vendor") -> Cole LLC | D14: =Vendor_Invoices_AP!E11 -> 1466.07 | E14: =COUNTIF(Payment_Log_AP!$B$2:$B$753,A14) -> 1 | F14: =SUMIFS(Payment_Log_AP!$E$2:$E$753,Payment_Log_AP!$B$2:$B$753,A14) -> 1466.07 | G14: =MAX(F14-D14,0) -> 0 | H14: =IF(E14>1,"DUPLICATE - Review",IF(G14>Assumptions!$B$6,"OVERPAID - Review","OK")) -> OK
A15: =Vendor_Invoices_AP!A12 -> INV30011 | B15: =Vendor_Invoices_AP!C12 -> V1024 | C15: =IFERROR(INDEX(Vendor_Master!$B$2:$B$41,MATCH(B15,Vendor_Master!$A$2:$A$41,0)),"Unknown Vendor") -> Campos Inc | D15: =Vendor_Invoices_AP!E12 -> 760.24 | E15: =COUNTIF(Payment_Log_AP!$B$2:$B$753,A15) -> 0 | F15: =SUMIFS(Payment_Log_AP!$E$2:$E$753,Payment_Log_AP!$B$2:$B$753,A15) -> 0 | G15: =MAX(F15-D15,0) -> 0 | H15: =IF(E15>1,"DUPLICATE - Review",IF(G15>Assumptions!$B$6,"OVERPAID - Review","OK")) -> OK
A16: =Vendor_Invoices_AP!A13 -> INV30012 | B16: =Vendor_Invoices_AP!C13 -> V1035 | C16: =IFERROR(INDEX(Vendor_Master!$B$2:$B$41,MATCH(B16,Vendor_Master!$A$2:$A$41,0)),"Unknown Vendor") -> Allen PLC | D16: =Vendor_Invoices_AP!E13 -> 15002.72 | E16: =COUNTIF(Payment_Log_AP!$B$2:$B$753,A16) -> 1 | F16: =SUMIFS(Payment_Log_AP!$E$2:$E$753,Payment_Log_AP!$B$2:$B$753,A16) -> 15002.72 | G16: =MAX(F16-D16,0) -> 0 | H16: =IF(E16>1,"DUPLICATE - Review",IF(G16>Assumptions!$B$6,"OVERPAID - Review","OK")) -> OK
... A885: =Vendor_Invoices_AP!A882 -> INV30881 | B885: =Vendor_Invoices_AP!C882 -> V1014 | C885: =IFERROR(INDEX(Vendor_Master!$B$2:$B$41,MATCH(B885,Vendor_Master!$A$2:$A$41,0)),"Unknown Vendor") -> Flowers, Martin and Kelly | D885: =Vendor_Invoices_AP!E882 -> 4104.49 | E885: =COUNTIF(Payment_Log_AP!$B$2:$B$753,A885) -> 1 | F885: =SUMIFS(Payment_Log_AP!$E$2:$E$753,Payment_Log_AP!$B$2:$B$753,A885) -> 4104.49 | G885: =MAX(F885-D885,0) -> 0 | H885: =IF(E885>1,"DUPLICATE - Review",IF(G885>Assumptions!$B$6,"OVERPAID - Review","OK")) -> OK

Sheet AP_Payment_Detail
A1: Helper Table — AP Payment Detail (feeds DPO_Summary trend)
A2: One row per AP payment with its matched invoice date, used to compute actual days-to-pay by month.
A4: Payment_ID | B4: Vendor_ID | C4: Invoice_ID | D4: Payment_Date | E4: Payment_Amount | F4: Invoice_Date | G4: Days_To_Pay | H4: Month_Key
A5: =Payment_Log_AP!A2 -> PAY40001 | B5: =Payment_Log_AP!C2 -> V1020 | C5: =Payment_Log_AP!B2 -> INV30001 | D5: =Payment_Log_AP!D2 -> 46142 | E5: =Payment_Log_AP!E2 -> 1417.41 | F5: =IFERROR(INDEX(Vendor_Invoices_AP!$D$2:$D$882,MATCH(C5,Vendor_Invoices_AP!$A$2:$A$882,0)),"") -> 46109 | G5: =IF(F5="","",D5-F5) -> 33 | H5: =IF(F5="","",DATE(YEAR(D5),MONTH(D5),1)) -> 46113
A6: =Payment_Log_AP!A3 -> PAY40002 | B6: =Payment_Log_AP!C3 -> V1034 | C6: =Payment_Log_AP!B3 -> INV30002 | D6: =Payment_Log_AP!D3 -> 45805 | E6: =Payment_Log_AP!E3 -> 1749.66 | F6: =IFERROR(INDEX(Vendor_Invoices_AP!$D$2:$D$882,MATCH(C6,Vendor_Invoices_AP!$A$2:$A$882,0)),"") -> 45803 | G6: =IF(F6="","",D6-F6) -> 2 | H6: =IF(F6="","",DATE(YEAR(D6),MONTH(D6),1)) -> 45778
A7: =Payment_Log_AP!A4 -> PAY40003 | B7: =Payment_Log_AP!C4 -> V1014 | C7: =Payment_Log_AP!B4 -> INV30003 | D7: =Payment_Log_AP!D4 -> 45683 | E7: =Payment_Log_AP!E4 -> 2691.35 | F7: =IFERROR(INDEX(Vendor_Invoices_AP!$D$2:$D$882,MATCH(C7,Vendor_Invoices_AP!$A$2:$A$882,0)),"") -> 45676 | G7: =IF(F7="","",D7-F7) -> 7 | H7: =IF(F7="","",DATE(YEAR(D7),MONTH(D7),1)) -> 45658
A8: =Payment_Log_AP!A5 -> PAY40004 | B8: =Payment_Log_AP!C5 -> V1040 | C8: =Payment_Log_AP!B5 -> INV30004 | D8: =Payment_Log_AP!D5 -> 45805 | E8: =Payment_Log_AP!E5 -> 889.24 | F8: =IFERROR(INDEX(Vendor_Invoices_AP!$D$2:$D$882,MATCH(C8,Vendor_Invoices_AP!$A$2:$A$882,0)),"") -> 45783 | G8: =IF(F8="","",D8-F8) -> 22 | H8: =IF(F8="","",DATE(YEAR(D8),MONTH(D8),1)) -> 45778
A9: =Payment_Log_AP!A6 -> PAY40005 | B9: =Payment_Log_AP!C6 -> V1022 | C9: =Payment_Log_AP!B6 -> INV30005 | D9: =Payment_Log_AP!D6 -> 45883 | E9: =Payment_Log_AP!E6 -> 3058.04 | F9: =IFERROR(INDEX(Vendor_Invoices_AP!$D$2:$D$882,MATCH(C9,Vendor_Invoices_AP!$A$2:$A$882,0)),"") -> 45861 | G9: =IF(F9="","",D9-F9) -> 22 | H9: =IF(F9="","",DATE(YEAR(D9),MONTH(D9),1)) -> 45870
A10: =Payment_Log_AP!A7 -> PAY40006 | B10: =Payment_Log_AP!C7 -> V1040 | C10: =Payment_Log_AP!B7 -> INV30006 | D10: =Payment_Log_AP!D7 -> 46160 | E10: =Payment_Log_AP!E7 -> 1359.77 | F10: =IFERROR(INDEX(Vendor_Invoices_AP!$D$2:$D$882,MATCH(C10,Vendor_Invoices_AP!$A$2:$A$882,0)),"") -> 46132 | G10: =IF(F10="","",D10-F10) -> 28 | H10: =IF(F10="","",DATE(YEAR(D10),MONTH(D10),1)) -> 46143
A11: =Payment_Log_AP!A8 -> PAY40007 | B11: =Payment_Log_AP!C8 -> V1040 | C11: =Payment_Log_AP!B8 -> INV30007 | D11: =Payment_Log_AP!D8 -> 46193 | E11: =Payment_Log_AP!E8 -> 3708.39 | F11: =IFERROR(INDEX(Vendor_Invoices_AP!$D$2:$D$882,MATCH(C11,Vendor_Invoices_AP!$A$2:$A$882,0)),"") -> 46188 | G11: =IF(F11="","",D11-F11) -> 5 | H11: =IF(F11="","",DATE(YEAR(D11),MONTH(D11),1)) -> 46174
A12: =Payment_Log_AP!A9 -> PAY40008 | B12: =Payment_Log_AP!C9 -> V1015 | C12: =Payment_Log_AP!B9 -> INV30008 | D12: =Payment_Log_AP!D9 -> 45859 | E12: =Payment_Log_AP!E9 -> 6081.19 | F12: =IFERROR(INDEX(Vendor_Invoices_AP!$D$2:$D$882,MATCH(C12,Vendor_Invoices_AP!$A$2:$A$882,0)),"") -> 45833 | G12: =IF(F12="","",D12-F12) -> 26 | H12: =IF(F12="","",DATE(YEAR(D12),MONTH(D12),1)) -> 45839
A13: =Payment_Log_AP!A10 -> PAY40009 | B13: =Payment_Log_AP!C10 -> V1005 | C13: =Payment_Log_AP!B10 -> INV30010 | D13: =Payment_Log_AP!D10 -> 45885 | E13: =Payment_Log_AP!E10 -> 1466.07 | F13: =IFERROR(INDEX(Vendor_Invoices_AP!$D$2:$D$882,MATCH(C13,Vendor_Invoices_AP!$A$2:$A$882,0)),"") -> 45878 | G13: =IF(F13="","",D13-F13) -> 7 | H13: =IF(F13="","",DATE(YEAR(D13),MONTH(D13),1)) -> 45870
A14: =Payment_Log_AP!A11 -> PAY40010 | B14: =Payment_Log_AP!C11 -> V1035 | C14: =Payment_Log_AP!B11 -> INV30012 | D14: =Payment_Log_AP!D11 -> 45989 | E14: =Payment_Log_AP!E11 -> 15002.72 | F14: =IFERROR(INDEX(Vendor_Invoices_AP!$D$2:$D$882,MATCH(C14,Vendor_Invoices_AP!$A$2:$A$882,0)),"") -> 45975 | G14: =IF(F14="","",D14-F14) -> 14 | H14: =IF(F14="","",DATE(YEAR(D14),MONTH(D14),1)) -> 45962
A15: =Payment_Log_AP!A12 -> PAY40011 | B15: =Payment_Log_AP!C12 -> V1016 | C15: =Payment_Log_AP!B12 -> INV30013 | D15: =Payment_Log_AP!D12 -> 46196 | E15: =Payment_Log_AP!E12 -> 911.91 | F15: =IFERROR(INDEX(Vendor_Invoices_AP!$D$2:$D$882,MATCH(C15,Vendor_Invoices_AP!$A$2:$A$882,0)),"") -> 46176 | G15: =IF(F15="","",D15-F15) -> 20 | H15: =IF(F15="","",DATE(YEAR(D15),MONTH(D15),1)) -> 46174
A16: =Payment_Log_AP!A13 -> PAY40012 | B16: =Payment_Log_AP!C13 -> V1002 | C16: =Payment_Log_AP!B13 -> INV30014 | D16: =Payment_Log_AP!D13 -> 45753 | E16: =Payment_Log_AP!E13 -> 1222.88 | F16: =IFERROR(INDEX(Vendor_Invoices_AP!$D$2:$D$882,MATCH(C16,Vendor_Invoices_AP!$A$2:$A$882,0)),"") -> 45740 | G16: =IF(F16="","",D16-F16) -> 13 | H16: =IF(F16="","",DATE(YEAR(D16),MONTH(D16),1)) -> 45748
... A756: =Payment_Log_AP!A753 -> PAY40752 | B756: =Payment_Log_AP!C753 -> V1014 | C756: =Payment_Log_AP!B753 -> INV30881 | D756: =Payment_Log_AP!D753 -> 46002 | E756: =Payment_Log_AP!E753 -> 4104.49 | F756: =IFERROR(INDEX(Vendor_Invoices_AP!$D$2:$D$882,MATCH(C756,Vendor_Invoices_AP!$A$2:$A$882,0)),"") -> 45973 | G756: =IF(F756="","",D756-F756) -> 29 | H756: =IF(F756="","",DATE(YEAR(D756),MONTH(D756),1)) -> 45992

Sheet DPO_Summary
A1: Accounts Payable — Days Payable Outstanding (DPO)
A2: Headline formula-based DPO, plus an actual average days-to-pay trend by month from AP_Payment_Detail.
A4: Headline DPO (formula method)
A5: Ending AP (Outstanding Balance, all invoices) | B5: =SUM(AP_Aging!$B$890:$B$893) -> 569517.22
A6: Total AP Invoiced (full data period) | B6: =SUM(Vendor_Invoices_AP!$E$2:$E$882) -> 3067975.3
A7: Days in Period (data span) | B7: =MAX(Vendor_Invoices_AP!$D$2:$D$882)-MIN(Vendor_Invoices_AP!$D$2:$D$882) -> 558
A8: DPO = Ending AP / Total AP Invoiced x Days in Period | B8: =B5/B6*B7 -> 103.58317
A9: Actual Average Days-to-Pay (all settled invoices) | B9: =AVERAGE(AP_Payment_Detail!$G$5:$G$756) -> 17.986702
A11: Monthly Trend — Actual Average Days-to-Pay
A12: Month | B12: Avg Days to Pay | C12: Total Paid ($)
A13: 45658 | B13: =IFERROR(AVERAGEIFS(AP_Payment_Detail!$G$5:$G$756,AP_Payment_Detail!$H$5:$H$756,A13),0) -> 8.6666667 | C13: =SUMIFS(AP_Payment_Detail!$E$5:$E$756,AP_Payment_Detail!$H$5:$H$756,A13) -> 28576.85
